Workbook

Sheet PROCEDURE — Verify a PDF
A1: STANDARD PROCEDURE — RECONCILING A NEW BUDGET PDF INTO THIS WORKBOOK
B3: Replicated from the FY27 North Shore Wins reconciliation (Jul 8). Run these steps for every new source document so all figures stay consistent and tie to a verifiable total.
A5: 1 | B5: EXTRACT EVERY LINE — pull all organization/project rows, not just section totals (pdfplumber, all pages). Capture pot/category, organization, program note, source page ref, and amount.
A6: 2 | B6: VERIFY INTERNAL ARITHMETIC FIRST — before trusting any figure, confirm each subtotal sums to what the PDF prints, and that the sections sum to the grand total. Only proceed once every subtotal ties to the penny.
A7: 3 | B7: CROSS-REFERENCE TO THE MASTER — match the new rows against Master Line Items at pot/org level. Identical row-count + identical dollars + matching pots = consistent. Label-only differences (e.g. "Aging" vs "Aging Discretionary") are noted, not corrected.
A8: 4 | B8: APPLY D49 ATTRIBUTION (location-first, per standing EIN policy) — for each row: resolve the organization's location. If the facility is physically in a D49 zip (10301/02/03/04/10) it is IN D49 even when funded via Speaker/Delegation/non-city channels. If out-of-district but the purpose text says "Council District 49," it is TO D49. Flag corrections with a ✎ and a citation.
A9: 5 | B9: LABEL THE PROVENANCE TIER — ADOPTED (printed record) / ADOPTED-IMPLEMENTATION (allocated, clearing) / DELIBERATIVE (pending verification) / CONTEXT. Never mix tiers in one total; never merge separate bases (e.g. North-Shore citywide subset vs full-SI citywide).
A10: 6 | B10: RECONCILE TO THE INDEPENDENT FIGURE — confirm the grand ties to any external check (e.g. the colleague's ChatGPT North Shore Total $35,903,925). A TIES ✓ formula records the match so it re-checks on every open.
A11: 7 | B11: LOG ANY SCOPE DIFFERENCES AS F-ITEMS — differences that are scope not error (e.g. F11 Speaker $900K North-Shore view vs $825K strict tag; F12 Delegation $7.0M NS vs $7,418,000 full-SI) go in the Discrepancy Log with a resolution note, so they are never mistaken for mistakes.
A12: 8 | B12: PROPAGATE EVERYWHERE — write the detail tab, update Master/Reconcile/Finder, and re-run recalc.py to confirm zero formula errors before shipping.
B14: RESULT STANDARD: every figure carries a source page, a provenance tier, and a D49 status; every subtotal ties by formula; and the grand reconciles to an independent total. This is the house method for all budget documents going forward.

Sheet Grand Total — Combined (Jul 7)
A1: FY27 STATEN ISLAND — COMBINED GRAND TOTAL, ALL CHANGES APPLIED, TIED TO PDF
A2: Every figure below is a live formula pulling from the PDF detail tabs in this workbook. Column B = corrected (ruling F1). Column C = as printed in the All-Funding PDF. TIES checks confirm the numbers meet the PDF.
A4: SECTION 1 — CAPITAL (identical in both columns)
A5: Component | B5: Corrected | C5: As printed (PDF) | D5: Basis / source
A6: Hanks — 22 lines | B6: ='PDF Capital Detail'!D26 -> 17750000 | C6: ='PDF Capital Detail'!D26 -> 17750000 | D6: PDF Capital Detail tab, section total
A7: Carr — 34 lines | B7: ='PDF Capital Detail'!D62 -> 15600000 | C7: ='PDF Capital Detail'!D62 -> 15600000 | D7: PDF Capital Detail tab
A8: Morano — 30 lines | B8: ='PDF Capital Detail'!D94 -> 10536000 | C8: ='PDF Capital Detail'!D94 -> 10536000 | D8: PDF Capital Detail tab
A9: SI Delegation — 3 lines | B9: ='PDF Capital Detail'!D99 -> 7418000 | C9: ='PDF Capital Detail'!D99 -> 7418000 | D9: PDF Capital Detail tab
A10: Speaker (pure) — 5 lines incl. MA1004 | B10: ='PDF Capital Detail'!D106 -> 26046000 | C10: ='PDF Capital Detail'!D106 -> 26046000 | D10: PDF Capital Detail tab
A11: CAPITAL TOTAL | B11: =SUM(B6:B10) -> 77350000 | C11: =SUM(C6:C10) -> 77350000 | D11: PDF states $77,350,000
A13: SECTION 2 — EXPENSE
A14: Baseline CM allocated pots (45 rows) | B14: ='PDF Member Pots'!C55 -> 6773000 | C14: ='PDF Member Pots'!C55 -> 6773000 | D14: PDF Member Pots tab: Hanks $2,295,000 + Carr $2,270,000 + Morano $2,208,000
A15: Speaker initiatives — corrected (34 rows) | B15: ='Speaker Reconcile (Jul 7)'!D42 -> 2817880 | C15: ='Speaker Reconcile (Jul 7)'!D40 -> 2867880 | D15: Corrected = PDF $2,867,880 less Ulqin $25,000 + Project Hospitality $25,000 (ruling F1)
A16: Citywide initiatives (90 rows) | B16: ='PDF Citywide Lines'!C95 -> 8341467 | C16: ='PDF Citywide Lines'!C95 -> 8341467 | D16: PDF Citywide Lines tab
A17: EXPENSE TOTAL | B17: =SUM(B14:B16) -> 17932347 | C17: =SUM(C14:C16) -> 17982347 | D17: PDF states $17,982,347 (as-printed) · corrected $17,932,347
A19: SECTION 3 — GRAND TOTAL & TIE TO PDF
A20: CAPITAL + EXPENSE — GRAND TOTAL | B20: =B11+B17 -> 95282347 | C20: =C11+C17 -> 95332347
A21: PDF target — as printed | C21: 95332347 | D21: All-Funding PDF, page 1: "All-In Total: $95,332,347"
A22: TIE CHECK — as printed vs PDF | C22: =IF(C20=C21,"TIES ✓","CHECK Δ "&TEXT(C20-C21,"$#,##0")) -> TIES ✓
A23: Corrected grand total (ruling F1 applied) | B23: =B20 -> 95282347 | D23: Equals as-printed $95,332,347 less $50,000 (Ulqin + Project Hospitality out of Speaker)
A24: TIE CHECK — corrected = printed − $50,000 | B24: =IF(B23=C21-50000,"TIES ✓","CHECK") -> TIES ✓
A26: SECTION 4 — BRIDGE: WORKBOOK BASIS → PDF BASIS (every dollar of difference accounted)
A27: Workbook printed SI grand total (Grand Total tab basis) | B27: 93661240 | D27: Capital $77,350,000 + MDI $6,638,000 + Delegation $120,000 + Speaker $2,817,880 + other-CM MDI $92,000 + Citywide $6,553,360 + SU-CASA $90,000
A28: + Citywide dollars in PDF basis only (13 org groups $1,603,107 + IlluminArt partial $75,000 − workbook-only row $10,000) | B28: 1668107 | D28: Citywide Reconcile tab decomposition
A29: − Pot-allocation basis vs MDI-scan basis (pots $6,773,000 vs MDI $6,638,000 + other-CM $92,000 + SU-CASA $90,000 = $6,820,000) | B29: -47000 | D29: PDF counts pot allocations; workbook counts designated lines + DB items
A30: EQUALS: CORRECTED PDF-BASIS GRAND TOTAL | B30: =SUM(B27:B29) -> 95282347
A31: + Restore F1 rows (Ulqin $25,000 + Project Hospitality $25,000) → as printed | B31: =B30+50000 -> 95332347
A32: TIE CHECK — bridge reproduces PDF printed total | B32: =IF(B31=95332347,"TIES ✓","CHECK") -> TIES ✓
A33: TIE CHECK — bridge corrected = Section 3 corrected | B33: =IF(B30=B23,"TIES ✓","CHECK") -> TIES ✓
A35: Standing rule: the three bases (PDF as-printed, PDF corrected, workbook scan) remain separate measures. This tab exists to prove they meet — not to merge them. Official measures unchanged: A $74,812,000 · B $78,348,000 · C ≈$84,018,000.
A37: THE −$47,000 — DECOMPOSED AND RESOLVED (Jul 7, Hanks DB export)
A38: + SU-CASA allocations counted in PDF pot basis ($45,000 × 3 members) | B38: 135000
A39: − SU-CASA designated per July DB (Carr $45,000 + Morano $45,000) | B39: -90000
A40: − Other-CM dollars reaching SI, invisible to a pots view (MAS Bklyn&SI $85,000 + Vernikov→JCC Sunrise $7,000) | B40: -92000
A41: EQUALSnet pot-basis vs scan-basis difference | B41: =SUM(B38:B40) -> -47000
A42: RESOLVED: the Hanks 07-07-26 designation export contains ZERO SU-CASA rows — the undesignated $45,000 is CM HANKS’S. Action: designate before the window closes. See D49 Funding Finder tab.

Sheet D49 Attribution (corrected)
A1: DISTRICT 49 ATTRIBUTION — CORRECTED (Jul 8, per Omar) & LOCATION-VERIFIED
A2: Applies three D49 corrections and re-combs every North Shore component for in-district location. North Shore Total $35,903,925 confirmed = colleague's ChatGPT figure.
A4: Component | B4: Amount | C4: Category | D4: Location / Evidence | E4: D49 status
A5: Hanks Expense — 183 base orgs | B5: 2250000 | C5: MDI expense | D5: All rows tagged Council District 49 | E5: IN D49
A6: Hanks SU-CASA | B6: 45000 | C6: MDI expense | D6: Post-adoption; senior sites in D49 | E6: IN D49 (undesignated flag)
A7: Speaker — NYCID Credible Messengers | B7: 500000 | C7: Speaker | D7: SI-wide, HQ New Brighton 10310 | E7: IN D49
A8: Speaker — Chamber "49th Council District" | B8: 75000 | C8: Speaker | D8: CORRECTED: labeled 49th CD → Hanks/D49 (was blank sponsor) | E8: IN D49 ✎
A9: Speaker — Universal Temple Love In Bloom | B9: 50000 | C9: Speaker | D9: Stapleton 10304 | E9: IN D49
A10: Speaker — On Your Mark | B10: 35000 | C10: Speaker | D10: Pleasant Plains — serves D49 program | E10: TO D49
A11: Speaker — Atlas Foundation | B11: 30000 | C11: Speaker | D11: West Brighton 10310 | E11: IN D49
A12: Speaker — Dibra Community Org | B12: 25000 | C12: Speaker | D12: SI immigrant services | E12: TO D49
A13: Speaker — City Parks SummerStage CD49 | B13: 110000 | C13: Speaker | D13: p.358 — explicitly CD49 | E13: IN D49
A14: Speaker — JCC Social Adult Day Care | B14: 25000 | C14: Speaker | D14: p.392 — Stapleton | E14: IN D49
A15: Speaker — SI Immigrant Center | B15: 50000 | C15: Speaker | D15: p.441 — St. George | E15: IN D49
A16: Hanks Capital — 22 projects | B16: 17750000 | C16: Capital | D16: All §254 projects in CD49 | E16: IN D49
... A19: Non-City Capital — St. George Theatre | B19: 5850000 | C19: Non-city capital | D19: CORRECTED: 35 Hyatt St 10301 → IN D49 (MA1004) | E19: IN D49 ✎
A20: D49-LOCATED SUBTOTAL (all directly in/to District 49) | B20: =SUM(B5:B19) -> 33795000
A21: + Citywide initiatives to D49/NS orgs (separate basis) | B21: 2108925
A22: EQUALS NORTH SHORE TOTAL | B22: =B20+B21 -> 35903925
A23: ChatGPT / colleague figure $35,903,925 — tie check | B23: =IF(B22=35903925,"TIES ✓","CHECK") -> TIES ✓
A25: ✎ = corrected D49 attribution this pass. Snug Harbor, SI Zoo, and St. George Theatre are all physically within District 49 (North Shore), so their capital is D49-located even though sponsored via Delegation/non-city channels. The $75K Chamber "49th Council District" speaker item is Hanks/D49 despite a blank sponsor tag.

Sheet D49 Citywide — Missed Lines
A1: DISTRICT 49 CITYWIDE FUNDING — LINES BEYOND THE COLLEAGUE'S $2,108,925
A2: Colleague's 22-line figure is a defensible conservative floor (program-specific D49). This tab adds what his method missed, in two clearly-separated tiers so the two rules are never conflated.
A4: THE THREE DEFENSIBLE D49 CITYWIDE NUMBERS
A5: A · Colleague conservative — program names/serves D49 specifically (22 lines) | B5: 2108925 | C5: FLOOR — safest for mailer/oversight
A6: B · + Tier 1: program-specific lines he missed by his own rule (2 lines) | B6: 2144925 | C6: his rule, applied consistently
A7: C · + Tier 2: all D49-anchored orgs, any program scope (27 lines) | B7: 5807090 | C7: org-location rule — broadest defensible
A9: TIER 1 — MISSED BY HIS OWN RULE (program explicitly names a D49 school)
A10: Organization / Program | B10: Amount | C10: Initiative | D10: D49 marker
A11: Sundog Theatre, Inc. - Curtis High School (31R450) | B11: 18000 | C11: Violence Prevention and Intervention for Youth | D11: names a D49 school (Curtis HS / I.S. 49R)
A12: Sundog Theatre, Inc. - I.S. 49R Berta A. Dreyfus (31R049) | B12: 18000 | C12: Violence Prevention and Intervention for Youth | D12: names a D49 school (Curtis HS / I.S. 49R)
A13: TIER 1 SUBTOTAL | B13: =SUM(B11:B12) -> 36000
A15: TIER 2 — D49-ANCHORED ORG, BOROUGH/CITYWIDE PROGRAM SCOPE (org-location rule)
A16: These orgs are physically in D49 but the program serves the whole borough/city. Include only if using an org-location definition, not the program-scope rule.
A17: Organization | B17: Amount | C17: Initiative | D17: D49 location
A18: Pride Center of Staten Island, Inc. | B18: 444375 | C18: LGBTQIA+ Community Services | D18: St. George 10301
A19: Community Health Action of Staten Island, Inc. | B19: 363752 | C19: HIV/AIDS Pathways to Care | D19: Stapleton 10304
A20: Community Health Action of Staten Island, Inc. | B20: 350000 | C20: Opioid Prevention and Treatment | D20: Stapleton 10304
A21: Pride Center of Staten Island, Inc. | B21: 320000 | C21: Trans Equity Programs | D21: St. George 10301
A22: Richmond Medical Center | B22: 259000 | C22: Court-Involved Youth Mental Health Initiative | D22: West Brighton 10310
A23: Community Health Center of Richmond, Inc. | B23: 233523 | C23: Healthy Beginnings | D23: West Brighton 10310
A24: Pride Center of Staten Island, Inc. | B24: 130000 | C24: LGBTQIA+ Youth Support and Services | D24: St. George 10301
A25: Richmond Medical Center | B25: 107103 | C25: Developmental, Psychological and Behavioral Health Services | D25: West Brighton 10310
A26: Staten Island Community Job Center, Inc. | B26: 100000 | C26: Culturally Specific Gender Based Violence | D26: Port Richmond 10302
A27: Project Hospitality, Inc. | B27: 100000 | C27: LGBTQIA+ Youth Support and Services | D27: Stapleton 10304
A28: Richmond Medical Center | B28: 100000 | C28: Initiative to Combat Sexual Assault | D28: West Brighton 10310
A29: Pride Center of Staten Island, Inc. | B29: 100000 | C29: LGBTQIA+ Older Adult Services in Every Borough | D29: St. George 10301
... A45: Camelot of Staten Island, Inc. | B45: 10000 | C45: Boroughwide Needs | D45: Stapleton 10304
A46: TIER 2 SUBTOTAL | B46: =SUM(B18:B45) -> 3662165
A48: RECOMMENDATION: cite $2,108,925 (A) as the conservative "District 49 citywide wins" figure — every dollar is a program that names/serves D49, the safest claim. Use $5,807,090 (C) only for an internal "D49-anchored org" tally, always labeled as org-location basis. Never state a bare number without its rule.

Sheet D49 Evidence & Pages
A1: DISTRICT 49 — WHERE EVERY DOLLAR LIVES: SCHEDULE C PAGES, LOCATION, AND THE PRINTED D49 EVIDENCE
A2: Four channels, labeled separately. Expense channels locate in Schedule C by page; capital locates in Section 254 by CC/MA project ID (different document). Location from MOCS DB addresses; evidence quoted from CM Purpose / Program / printed org strings.
A4: A · HANKS FY27 MDI DESIGNATIONS — BY ORGANIZATION
A5: Organization | B5: EIN | C5: FY27 $ | D5: Sched C page(s) | E5: Zip | F5: Location classification | G5: Evidence keywords | H5: Evidence quote (CM Purpose / Program)
A6: Department of Parks and Recreation | B6: 13-6400434 | C6: 274000 | D6: App B p.107; App B p.110; App B p.111; App B p.112; App B p.62; App B p.63; App B p.64; App B p.65; App B p.66; App B p.67; App B p.69; p.112; p.191 | E6: 10007 | F6: OUTSIDE SI — WORKING IN D49 (text evidence) | G6: port richmond | H6: …Funding will support Port Richmond High School (31R445) Parent Tenant Association. | Port Richmond High Sc…
A7: Staten Island Chamber of Commerce Foundati | B7: 13-4069282 | C7: 95000 | D7: App B p.136; p.115; p.214 | E7: 10314 | F7: SI — OTHER DISTRICT AREA | G7: district 49, rosebank | H7: …ess Expo & Rosebank Holiday Event in Council District 49. | Women in Business Expo & Rosebank Holiday Event - Council District 49…
A8: Staten Island Economic Development Corpora | B8: 13-3706442 | C8: 85000 | D8: App B p.136; p.115; p.214 | E8: 10314 | F8: SI — OTHER DISTRICT AREA | G8: district 49 | H8: …port clean ups and beautification in Council District 49 | Council District 49 | Staten Island Economic Development Corporation…
A9: Community Agency for Senior Citizens, Inc. | B9: 13-3263537 | C9: 80000 | D9: App A p.6; p.176; p.77 | E9: 10301 | F9: LOCATED IN D49 (North Shore zip) | G9: district 49 | H9: …tywide domestic violence services. | Council District 49 | Community Agency for Senior Citizens, Inc.…
A10: New York Center for Interpersonal Developm | B10: 23-7085239 | C10: 80000 | D10: PDF p.58 (member listing) | E10: 10301 | F10: LOCATED IN D49 (North Shore zip) | G10: district 49 | H10: …rt the Credible Messenger program in Council District 49. | Council District 49 | New York Center for Interpersonal Development, I…
A11: Dr. Theodore A. Atlas Foundation, Inc. | B11: 13-4012789 | C11: 70000 | D11: App B p.70; App C p.163; PDF p.12 (member listing) | E11: 10310 | F11: LOCATED IN D49 (North Shore zip) | G11: district 49 | H11: …ion and turkey giveaways services in Council District 49. | Food Distribution - Council District 49 | Dr. Theodore A. Atlas Founda…
A12: City Parks Foundation | B12: 13-3561657 | C12: 61000 | D12: App B p.54; p.100; p.189 | E12: 10065 | F12: OUTSIDE SI — WORKING IN D49 (text evidence) | G12: district 49 | H12: …CityParks Learn & CityParks Build - Council District 49 | City Parks Foundation…
A13: Catholic Charities of Staten Island | B13: 13-5562286 | C13: 60000 | D13: App A p.5; p.175 | E13: 10309 | F13: SI — OTHER DISTRICT AREA | G13: district 49 | H13: …derson Neighborhood Senior Center in Council District 49. | Anderson Neighborhood Older Adult Center | Catholic Charities of State…
A14: Justice Innovation, Inc. | B14: 85-2810883 | C14: 60000 | D14: App C p.174; p.81 | E14: 10018 | F14: OUTSIDE SI — WORKING IN D49 (text evidence) | G14: district 49 | H14: …tywide domestic violence services. | Council District 49 | Justice Innovation, Inc.…
A15: Jewish Community Center of Staten Island, | B15: 13-5562256 | C15: 50000 | D15: App A p.14; p.103; p.180; p.67 | E15: 10314 | F15: SI — OTHER DISTRICT AREA | G15: stapleton | H15: …ng will support programs and services at the Stapleton Older Adult Center. | Stapleton Older Adult Center | Jewish Community Cente…
A16: Snug Harbor Cultural Center and Botanical | B16: 80-0193388 | C16: 50000 | D16: p.106; p.56; p.70 | E16: 10301 | F16: LOCATED IN D49 (North Shore zip) | G16: district 49, snug harbor | H16: …ce Development & Education Program - Council District 49 | Snug Harbor Cultural Center and Botanical Garden…
A17: Association of Community Employment Progra | B17: 13-3846431 | C17: 50000 | D17: p.189 | E17: 11101 | F17: OUTSIDE SI — WORKING IN D49 (text evidence) | G17: district 49 | H17: …eer groups. | Tappen Park Clean Up - Council District 49 | Association of Community Employment Programs for the Homeless, Inc.…
A18: Ballroom Basix USA, Inc. | B18: 27-3218865 | C18: 40000 | D18: App B p.35; p.32; p.61 | E18: 10035 | F18: OUTSIDE SI — WORKING IN D49 (text evidence) | G18: port richmond | H18: …to support programming in Public School 020R Port Richmond (31R020). | Public School 020R Port Richmond (31R020) | Ballroom Basix…
A19: Staten Island Institute of Arts and Scienc | B19: 13-5564127 | C19: 40000 | D19: p.56; p.57 | E19: 10301 | F19: LOCATED IN D49 (North Shore zip)
A20: West Brighton Community Local Development | B20: 13-3046424 | C20: 35000 | D20: App B p.145; p.15; p.215 | E20: 10310 | F20: LOCATED IN D49 (North Shore zip) | G20: west brighton | H20: …mall Business Technical Assistance Program | West Brighton Community Local Development Corporation…
A21: Citizens Committee for New York City, Inc. | B21: 51-0171818 | C21: 30000 | D21: PDF p.10 (member listing); p.100 | E21: 10035 | F21: OUTSIDE SI — WORKING IN D49 (text evidence) | G21: district 49 | H21: …spaces, and other vital resources. | Council District 49 | Citizens Committee for New York City, Inc.…
A22: Staten Island Community Services Friendshi | B22: 13-2778244 | C22: 30000 | D22: App A p.23; p.185 | E22: 10308 | F22: SI — OTHER DISTRICT AREA
A23: Canvas Institute | B23: 82-4902021 | C23: 30000 | D23: p.35; p.63 | E23: 10301 | F23: LOCATED IN D49 (North Shore zip) | G23: district 49 | H23: …that focus on immigrant heritages. | Council District 49 | Canvas Institute…
A24: Children's Aid Society, The | B24: 13-5562191 | C24: 30000 | D24: App C p.159; p.36 | E24: 10027 | F24: OUTSIDE SI — NO EXPLICIT D49 TEXT
A25: IlluminArt Productions | B25: 42-1727647 | C25: 30000 | D25: p.41; p.66 | E25: 10301 | F25: LOCATED IN D49 (North Shore zip)
A26: National Lighthouse Museum | B26: 13-4055215 | C26: 30000 | D26: p.49; p.68 | E26: 10301 | F26: LOCATED IN D49 (North Shore zip)
A27: Roundabout Theatre Company, Inc. | B27: 13-6192346 | C27: 30000 | D27: App B p.130; p.55 | E27: 10018 | F27: OUTSIDE SI — WORKING IN D49 (text evidence) | G27: port richmond | H27: …to students through after-school programs. | Port Richmond High School (31R445) | Roundabout Theatre Company, Inc.…
A28: Universal Temple of the Arts, Inc. | B28: 13-3335286 | C28: 30000 | D28: p.72 | E28: 10301 | F28: LOCATED IN D49 (North Shore zip) | G28: district 49 | H28: …that focus on immigrant heritages. | Council District 49 | Universal Temple of the Arts, Inc.…
A29: Staten Island Industrial Alliance/Northsho | B29: 92-2412852 | C29: 30000 | D29: p.15 | E29: 10303 | F29: LOCATED IN D49 (North Shore zip) | G29: district 49 | H29: …services. | Workforce Training Hub - Council District 49 | Staten Island Industrial Alliance/Northshore Leadership Alliance Corp.…
A30: Lifestyles for the Disabled, Inc. | B30: 13-3740011 | C30: 25000 | D30: App A p.15; App B p.94; p.181 | E30: 10314 | F30: SI — OTHER DISTRICT AREA | G30: district 49 | H30: …t the Serving Our Seniors program in Council District 49. | Serving Our Seniors - Council District 49 | Lifestyles for the Disable…
A31: Legal Services NYC | B31: 13-2600199 | C31: 25000 | D31: p.82 | E31: 10301 | F31: LOCATED IN D49 (North Shore zip) | G31: district 49 | H31: …tywide domestic violence services. | Council District 49 | Legal Services NYC…
A32: Seamen's Society for Children and Families | B32: 13-5563010 | C32: 25000 | D32: p.87 | E32: 10301 | F32: LOCATED IN D49 (North Shore zip) | G32: district 49 | H32: …tywide domestic violence services. | Council District 49 | Seamen's Society for Children and Families…
A33: Center For Hope Services, Inc. | B33: 88-2507208 | C33: 20000 | D33: App A p.5; p.175 | E33: 10305 | F33: D49 EDGE — 10305 (verify block) | G33: district 49 | H33: …ort the Age-Friendly Care program in Council District 49. | Age-Friendly Care Program - Council District 49 | Center For Hope Serv…
A34: On Your Mark, Inc. | B34: 13-3128315 | C34: 20000 | D34: PDF p.58 (member listing) | E34: 10301 | F34: LOCATED IN D49 (North Shore zip)
A35: Center for Educational Innovation | B35: 13-4113613 | C35: 20000 | D35: p.36 | E35: 10017 | F35: OUTSIDE SI — NO EXPLICIT D49 TEXT
A36: Marquis Studios, Ltd. | B36: 13-3047206 | C36: 20000 | D36: p.44 | E36: 11201 | F36: OUTSIDE SI — NO EXPLICIT D49 TEXT
A37: Noel Pointer Foundation, Inc. | B37: 11-3271472 | C37: 20000 | D37: p.50 | E37: 11216 | F37: OUTSIDE SI — NO EXPLICIT D49 TEXT
A38: Projectivity Group, Inc. | B38: 47-5358971 | C38: 20000 | D38: p.51 | E38: 10310 | F38: LOCATED IN D49 (North Shore zip)
A39: Staten Island Children's Museum | B39: 23-7379930 | C39: 20000 | D39: p.56 | E39: 10301 | F39: LOCATED IN D49 (North Shore zip)
A40: Staten Island Philharmonic Orchestra, Inc. | B40: 20-2732542 | C40: 20000 | D40: p.57 | E40: 10301 | F40: LOCATED IN D49 (North Shore zip) | G40: port richmond | H40: …to students through after-school programs. | Port Richmond High School (31R445) | Staten Island Philharmonic Orchestra, Inc.…
A41: Sundog Theatre, Inc. | B41: 45-0476945 | C41: 20000 | D41: p.58 | E41: 10301 | F41: LOCATED IN D49 (North Shore zip)
...

Sheet D49 Funding Finder
A1: DISTRICT 49 FUNDING FINDER — ALL CM HANKS / D49 DOLLARS, ONE PLACE
A2: Type any organization keyword in the yellow cell; every figure below it is a live formula over the FY25–27 designation register, the FY27 capital detail, and the Speaker lines. Components stay labeled separately per house rule.
A4: TYPE ORG KEYWORD → | B4: ZOOLOGICAL
A6: Result for keyword | B6: FY27 $ | C6: FY26 $ | D6: FY25 $ | E6: FY27 capital $ | F6: FY27 Speaker $ | G6: Lines matched | H6: Note
A7: Designations (MOCS DB 7-7) + FY27 capital + Speaker | B7: =SUMPRODUCT(--ISNUMBER(SEARCH($B$4,'Hanks D49 FY25–27 (DB 7-7)'!$C$4:$C$186&"")),'Hanks D49 FY25–27 (DB 7-7)'!$E$4:$E$186) -> 20000 | C7: =SUMPRODUCT(--ISNUMBER(SEARCH($B$4,'Hanks D49 FY25–27 (DB 7-7)'!$C$188:$C$389&"")),'Hanks D49 FY25–27 (DB 7-7)'!$E$188:$E$389) -> 20000 | D7: =SUMPRODUCT(--ISNUMBER(SEARCH($B$4,'Hanks D49 FY25–27 (DB 7-7)'!$C$391:$C$601&"")),'Hanks D49 FY25–27 (DB 7-7)'!$E$391:$E$601) -> 5000 | E7: =SUMPRODUCT(--ISNUMBER(SEARCH($B$4,'PDF Capital Detail'!$C$6:$C$107&"")),--('PDF Capital Detail'!$A$6:$A$107="HANKS"),'PDF Capital Detail'!$D$6:$D$107) -> 120000 | F7: =SUMPRODUCT(--ISNUMBER(SEARCH($B$4,'Speaker Reconcile (Jul 7)'!$C$4:$C$39&"")),--ISNUMBER(SEARCH("HANKS",'Speaker Reconcile (Jul 7)'!$A$4:$A$39&"")),--('Speaker Reconcile (Jul 7)'!$E$4:$E$39="Retained"),'Speaker Reconcile (Jul 7)'!$D$4:$D$39) -> 0 | G7: =SUMPRODUCT(--ISNUMBER(SEARCH($B$4,'Hanks D49 FY25–27 (DB 7-7)'!$C$4:$C$601&""))) -> 3 | H7: Capital/Speaker match on project/org text; verify EIN before citing
A10: DISTRICT 49 — FY27 ALL-IN STACK (components labeled; SI-shared pools listed but not district-split)
A11: Component | B11: Amount | C11: Basis
A12: Hanks MDI designations — 183 lines | B12: ='Hanks D49 FY25–27 (DB 7-7)'!E187 -> 2250000 | C12: MOCS/Council DB 07-07-26
A13: Hanks SU-CASA allocation — UNDESIGNATED | B13: 45000 | C13: $135,000 SI allocations − $90,000 DB = Hanks $45,000 with zero rows in export — ACTION: designate
A14: Hanks capital — 22 lines | B14: ='PDF Capital Detail'!D26 -> 17750000 | C14: Section 254 / All-Funding PDF
A15: Hanks-sponsored Speaker items | B15: 825000 | C15: $825K strict 6-item tag · North-Shore view $900K incl. Chamber 49th $75K, City Parks $110K, JCC SADC $25K, SI Immigrant $50K (corrected Jul 8) — see D49 Attribution tab
A16: D49 DIRECT TOTAL | B16: =SUM(B12:B15) -> 20870000 | C16: sum of the four lines above
A17: Memo — SI Delegation capital (shared, 3 lines) | B17: 7418000 | C17: serves all SI; not district-split
A18: Memo — SI Delegation expense pot (shared) | B18: 120000 | C18: Boroughwide Needs 11 rows
A19: Memo — Citywide-to-SI expense (shared) | B19: 8341467 | C19: PDF basis; org-level D49 reach via search box above
A20: Memo — Speaker pure capital + SI-tagged items (shared) | C20: Willowbrook, Bloomingdale, SIUH Prince, CSI lot, MA1004
A23: D49 ORGANIZATION ROLLUP — EVERY ORG FUNDED BY CM HANKS, FY25–FY27 (designation basis) + FY27 SPEAKER
A24: Organization (per DB) | B24: EIN | C24: FY27 $ | D24: FY26 $ | E24: FY25 $ | F24: FY27 Speaker $ | G24: 3-yr total $ | H24: Pots seen
A25: New York Center for Interpersonal Developmen | B25: 23-7085239 | C25: 80000 | D25: 80000 | E25: 80000 | F25: 500000 | G25: =SUM(C25:F25) -> 740000 | H25: Community Safety a
A26: Department of Sanitation | B26: 13-6400434 | C26: 180000 | D26: 150000 | E26: 200000 | G26: =SUM(C26:F26) -> 530000 | H26: NYC Cleanup
A27: Dr. Theodore A. Atlas Foundation, Inc. | B27: 13-4012789 | C27: 70000 | D27: 124500 | E27: 97500 | F27: 30000 | G27: =SUM(C27:F27) -> 322000 | H27: Aging; Anti-Poverty; Food Pantries; Lo
A28: City Parks Foundation | B28: 13-3561657 | C28: 61000 | D28: 45000 | E28: 25000 | F28: 110000 | G28: =SUM(C28:F28) -> 241000 | H28: A Greener NYC; Local; Parks Equity Ini
A29: Community Agency for Senior Citizens, Inc. | B29: 13-3263537 | C29: 80000 | D29: 70000 | E29: 90000 | G29: =SUM(C29:F29) -> 240000 | H29: Aging; Domestic Violence ; Support Our
A30: Staten Island Chamber of Commerce Foundation | B30: 13-4069282 | C30: 95000 | D30: 75000 | E30: 50000 | G30: =SUM(C30:F30) -> 220000 | H30: Local; NYC Cleanup; Neighborhood Devel
A31: Justice Innovation, Inc. | B31: 85-2810883 | C31: 60000 | D31: 60000 | E31: 60000 | G31: =SUM(C31:F31) -> 180000 | H31: Domestic Violence ; Youth
A32: Jewish Community Center of Staten Island, In | B32: 13-5562256 | C32: 50000 | D32: 50000 | E32: 50000 | F32: 25000 | G32: =SUM(C32:F32) -> 175000 | H32: A Greener NYC; Aging; Cultural Immigra
A33: Association of Community Employment Programs | B33: 13-3846431 | C33: 50000 | D33: 90000 | E33: 10000 | G33: =SUM(C33:F33) -> 150000 | H33: NYC Cleanup; Parks Equity Initi
A34: Department of Education | B34: 13-6400434 | C34: 49000 | D34: 49000 | E34: 44000 | G34: =SUM(C34:F34) -> 142000 | H34: Local
A35: IlluminArt Productions | B35: 42-1727647 | C35: 30000 | D35: 55000 | E35: 55000 | G35: =SUM(C35:F35) -> 140000 | H35: Cultural After-Sch; Cultural Immigrant
A36: Universal Temple of the Arts, Inc. | B36: 13-3335286 | C36: 30000 | D36: 30000 | E36: 28000 | F36: 50000 | G36: =SUM(C36:F36) -> 138000 | H36: Cultural Immigrant; Local
A37: Staten Island Economic Development Corporati | B37: 13-3706442 | C37: 85000 | D37: 35000 | E37: 15000 | G37: =SUM(C37:F37) -> 135000 | H37: Local; NYC Cleanup; Neighborhood Devel
A38: Snug Harbor Cultural Center & Botanical Gard | B38: 80-0193388 | D38: 65000 | E38: 65000 | G38: =SUM(C38:F38) -> 130000 | H38: A Greener NYC; Cultural After-Sch; Cul
A39: Seamen's Society for Children and Families | B39: 13-5563010 | C39: 25000 | D39: 25000 | E39: 75000 | G39: =SUM(C39:F39) -> 125000 | H39: Domestic Violence ; Local
A40: Catholic Charities of Staten Island | B40: 13-5562286 | C40: 60000 | D40: 30000 | E40: 30000 | G40: =SUM(C40:F40) -> 120000 | H40: Aging; Support Our Older
A41: Staten Island Institute of Arts and Sciences | B41: 13-5564127 | C41: 40000 | D41: 40000 | E41: 40000 | G41: =SUM(C41:F41) -> 120000 | H41: Cultural After-Sch
A42: Ballroom Basix USA, Inc. | B42: 27-3218865 | C42: 40000 | D42: 40000 | E42: 30000 | G42: =SUM(C42:F42) -> 110000 | H42: Cultural After-Sch; Cultural Immigrant
A43: West Brighton Community Local Development Co | B43: 13-3046424 | C43: 35000 | D43: 35000 | E43: 35000 | G43: =SUM(C43:F43) -> 105000 | H43: Digital Inclusion ; Local; Neighborhoo
A44: Staten Island Community Services Friendship | B44: 13-2778244 | C44: 30000 | D44: 30000 | E44: 30000 | G44: =SUM(C44:F44) -> 90000 | H44: Aging; Support Our Older
A45: Canvas Institute | B45: 82-4902021 | C45: 30000 | D45: 30000 | E45: 30000 | G45: =SUM(C45:F45) -> 90000 | H45: Cultural After-Sch; Cultural Immigrant
A46: Children's Aid Society, The | B46: 13-5562191 | C46: 30000 | D46: 30000 | E46: 30000 | G46: =SUM(C46:F46) -> 90000 | H46: Cultural After-Sch; Youth
...

Sheet Missed Items — Pages (Jul 7)
A1: ITEMS THE PDF FOUND THAT THE WORKBOOK SCAN MISSED — WITH SCHEDULE C PAGE TARGETS
A2: 26 rows · $1,703,107 · all now propagated into Master Line Items and Citywide-to-SI (yellow-flagged). Page targets derived from sibling rows in the same initiative; ranges are cluster estimates — confirm against the printed Schedule C before citing.
A4: Initiative | B4: Organization / Program | C4: EIN | D4: Amount | E4: Schedule C page target | F4: Status / note
A5: Welcome NYC | B5: Albanian-American Association of Ulqin, Inc. | C5: EIN PENDING | D5: 25000 | E5: p.151 (sibling: Dibra p.151) | F5: ADDED Jul 7 — PDF basis · was misfiled as Speaker
A6: Welcome NYC | B6: Dibra Community Organization, Inc. – New York City | C6: 27-4684048 | D6: 25000 | E6: p.151 (per Citywide tab) | F6: ADDED Jul 7 — F2 restore: was in Citywide tab, missing from Master
A7: LGBTQIA+ Youth Support and Services | B7: Project Hospitality, Inc. | C7: 13-3234441 | D7: 100000 | E7: p.228 (sibling: Pride Center p.228) | F7: ADDED Jul 7 — PDF basis
A8: Food Access and Benefits | B8: Project Hospitality, Inc. | C8: 13-3234441 | D8: 50000 | E8: search DOHMH/HRA cluster pp.122–171 | F8: ADDED Jul 7 — PDF basis · no sibling ref
A9: Children and Families in NYC Homeless System | B9: Project Hospitality, Inc. | C9: 13-3234441 | D9: 74000 | E9: search DHS/housing cluster pp.130–140 | F9: ADDED Jul 7 — PDF basis · no sibling ref
A10: Access Health Initiative | B10: Community Health Center of Richmond, Inc. | C10: EIN PENDING | D10: 93834 | E10: health cluster pp.122–127 | F10: ADDED Jul 7 — PDF basis
A11: Healthy Beginnings | B11: Community Health Center of Richmond, Inc. | C11: EIN PENDING | D11: 233523 | E11: p.123 (sibling: RMC p.123) | F11: ADDED Jul 7 — PDF basis
A12: MCCAP Initiative | B12: Community Health Center of Richmond, Inc. | C12: EIN PENDING | D12: 82000 | E12: p.125 (sibling: JCC p.125) | F12: ADDED Jul 7 — PDF basis
A13: Older Adults Mental Health | B13: Community Health Center of Richmond, Inc. | C13: EIN PENDING | D13: 50000 | E13: p.162 (sibling: JCC/CHCR p.162) | F13: ADDED Jul 7 — PDF basis
A14: Create New Technology Incubators | B14: City University of New York – College of Staten Island | C14: 13-3893536 (F7: confirm RF-CUNY) | D14: 500000 | E14: economic cluster pp.204–209 | F14: ADDED Jul 7 — PDF basis · EIN ruling F7 open
A15: Autism Awareness | B15: Grace Foundation of New York | C15: 13-4131863 | D15: 107372 | E15: p.156 (sibling: Eden II p.156) | F15: ADDED Jul 7 — PDF basis
A16: Coalition Theaters of Color | B16: Friends of Alice Austen House, Inc. | C16: 13-3248928 | D16: 70000 | E16: p.29 (sibling: Universal Temple p.29) | F16: ADDED Jul 7 — PDF basis
... A30: NYC RISE with Adult Literacy Forward | B30: Liberian Cultural Association, Inc. | C30: EIN PENDING | D30: 25000 | E30: p.18 (sibling: Adult Literacy p.18) | F30: ADDED Jul 7 — PDF basis
B31: TOTAL — MISSED ITEMS | D31: =SUM(D5:D30) -> 1703107
A33: EXACT-PAGE HITS (verify first, fastest wins): p.151 Welcome NYC (Ulqin, Dibra) · p.228 LGBTQIA+ Youth (PH) · p.123/125/162 CHCR trio · p.156 Grace · p.29 Alice Austen · p.170 SICS ×5 · p.163 IlluminArt opioid · p.18 Liberian.
A34: CLUSTER SEARCHES: DOHMH pp.122–171 (PH food/homeless, Atlas ×2, hate crimes) · economic/DSNY/SBS pp.204–209 (CUNY incubators, both BIDs) · youth pp.222–228 (Alice Austen students).
A35: EIN pulls outstanding (4): CHC Richmond · Ulqin · Liberian Cultural · New Dorp DMA — group census locks at 175+4 once pulled.

Sheet EIN Census (Jul 7)
A1: FY27 SI EXPENSE — UNIQUE ORGANIZATION CENSUS BY EIN · UPDATED WITH PDF BASIS (Jul 7)
A2: Basis: Master Line Items incl. 26 added PDF rows ($1,703,107). Category dollars labeled separately per house rule.
A4: EIN | B4: Organization (canonical) | C4: MDI SI-member $ | D4: MDI other-CM $ | E4: SI Delegation $ | F4: Speaker $ | G4: Citywide $ | H4: Expense total $ (this basis) | I4: Lines | J4: Name variants | K4: Sponsors seen
A5: 13-5562256 | B5: Jewish Community Center of Staten Island, Inc. | C5: 225000 | D5: 7000 | F5: 65000 | G5: 1048104 | H5: =SUM(C5:G5) -> 1345104 | I5: 28 | J5: 19 | K5: Carr; Hanks; Morano; Vernikov; —
A6: 47-2787706 | B6: La Colmena NYC, Inc. | G6: 1221666 | H6: =SUM(C6:G6) -> 1221666 | I6: 7 | J6: 3
A7: 46-3358895 | B7: Pride Center of Staten Island, Inc. | C7: 43000 | F7: 80000 | G7: 994375 | H7: =SUM(C7:G7) -> 1117375 | I7: 10 | J7: 5 | K7: Carr; Hanks; Morano; —
A8: 74-3177454 | B8: Richmond Medical Center | C8: 10000 | F8: 350000 | G8: 591797 | H8: =SUM(C8:G8) -> 951797 | I8: 8 | J8: 4 | K8: Carr; SI Delegation; —
A9: 13-3556132 | B9: Community Health Action of Staten Island, Inc. | C9: 65000 | G9: 799553 | H9: =SUM(C9:G9) -> 864553 | I9: 5 | J9: 3 | K9: Carr; Hanks
A10: 13-6400434 | B10: Department of Education | C10: 598500 | F10: 150000 | H10: =SUM(C10:G10) -> 748500 | I10: 91 | J10: 90 | K10: Carr; Hanks; Morano; —
A11: 23-7085239 | B11: New York Center for Interpersonal Development, Inc. | C11: 90000 | F11: 500000 | G11: 80000 | H11: =SUM(C11:G11) -> 670000 | I11: 4 | J11: 3 | K11: Carr; Hanks
A12: 13-3706442 | B12: Staten Island Economic Development Corporation | C12: 290000 | F12: 340000 | H12: =SUM(C12:G12) -> 630000 | I12: 17 | J12: 13 | K12: Carr; Carr+SI Del; Hanks; Morano; Morano
A13: 13-4069282 | B13: Staten Island Chamber of Commerce Foundation, Inc. | C13: 130000 | F13: 100000 | G13: 392765 | H13: =SUM(C13:G13) -> 622765 | I13: 12 | J13: 8 | K13: Carr; Hanks; Morano; SI Delegation; —
A14: 13-5680691 | B14: Staten Island Zoological Society, Inc. | C14: 125000 | F14: 417880 | H14: =SUM(C14:G14) -> 542880 | I14: 9 | J14: 8 | K14: Carr; Carr+Morano+SI Del; Hanks; Morano;
A15: 13-3893536 | B15: City University of New York | C15: 10000 | G15: 500000 | H15: =SUM(C15:G15) -> 510000 | I15: 2 | J15: 2 | K15: (citywide); Hanks
A16: 80-0193388 | B16: Careers & Stewardship Program Snug Harbor Cultural Center an | C16: 100000 | G16: 335000 | H16: =SUM(C16:G16) -> 435000 | I16: 7 | J16: 7 | K16: Carr; Hanks; Morano
A17: 42-1727647 | B17: IlluminArt Productions | C17: 240000 | G17: 155000 | H17: =SUM(C17:G17) -> 395000 | I17: 17 | J17: 14 | K17: (citywide); Carr; Hanks; Morano
A18: 45-0476945 | B18: Sundog Theatre, Inc. | C18: 297500 | G18: 42000 | H18: =SUM(C18:G18) -> 339500 | I18: 19 | J18: 18 | K18: Carr; Hanks; Morano
A19: 20-0404386 | B19: Heights Where to Turn, Inc. | C19: 305000 | H19: =SUM(C19:G19) -> 305000 | I19: 2 | J19: 2 | K19: Carr; Morano
A20: 13-2778244 | B20: Staten Island Community Services Friendship Clubs, Inc. | C20: 195000 | G20: 41665 | H20: =SUM(C20:G20) -> 236665 | I20: 14 | J20: 14 | K20: (citywide); Carr; Hanks; Morano
A21: 13-3234441 | B21: Project Hospitality, Inc. | C21: 5000 | G21: 224000 | H21: =SUM(C21:G21) -> 229000 | I21: 4 | J21: 2 | K21: (citywide); Morano
A22: 13-4131863 | B22: Grace Foundation of New York | C22: 55000 | E22: 10000 | F22: 50000 | G22: 107372 | H22: =SUM(C22:G22) -> 222372 | I22: 8 | J22: 4 | K22: (citywide); Carr; Carr+SI Del; Hanks; Mo
A23: 13-2974137 | B23: Northfield Community LDC of Staten Island, Inc. | G23: 213507 | H23: =SUM(C23:G23) -> 213507 | I23: 3 | J23: 3
A24: 13-2872916 | B24: Eden II School for Autistic Children, Inc. | C24: 50500 | E24: 15000 | F24: 25000 | G24: 109012 | H24: =SUM(C24:G24) -> 199512 | I24: 9 | J24: 7 | K24: Carr; Carr+Morano; Hanks; Morano; SI Del
A25: 13-1985514 | B25: Academy of Innovative Learning (31R065) Staten Island Histor | C25: 125000 | F25: 50000 | H25: =SUM(C25:G25) -> 175000 | I25: 8 | J25: 8 | K25: Carr; Carr+Morano+SI Del; Morano
A26: 13-3561657 | B26: City Parks Foundation | C26: 61000 | F26: 110000 | H26: =SUM(C26:G26) -> 171000 | I26: 4 | J26: 4 | K26: Hanks
A27: 45-3860014 | B27: New York City H2O | C27: 170000 | H27: =SUM(C27:G27) -> 170000 | I27: 8 | J27: 8 | K27: Carr; Hanks; Morano
A28: 13-3263537 | B28: Community Agency for Senior Citizens, Inc. | C28: 155000 | H28: =SUM(C28:G28) -> 155000 | I28: 8 | J28: 7 | K28: Carr; Hanks; Morano
A29: 13-5562286 | B29: Catholic Charities of Staten Island | C29: 150000 | H29: =SUM(C29:G29) -> 150000 | I29: 9 | J29: 8 | K29: Carr; Hanks; Morano
A30: 13-4012789 | B30: Dr. Theodore A. Atlas Foundation, Inc. | C30: 85000 | F30: 30000 | G30: 35000 | H30: =SUM(C30:G30) -> 150000 | I30: 9 | J30: 7 | K30: (citywide); Carr; Hanks
A31: 13-2921483 | B31: United Activities Unlimited, Inc. | C31: 100000 | F31: 50000 | H31: =SUM(C31:G31) -> 150000 | I31: 6 | J31: 2 | K31: Carr; Carr+SI Del; Morano
A32: 13-3335286 | B32: Universal Temple of the Arts, Inc. | C32: 30000 | F32: 50000 | G32: 70000 | H32: =SUM(C32:G32) -> 150000 | I32: 3 | J32: 3 | K32: Hanks
A33: 01-0873188 | B33: African Refuge, Inc. | F33: 50000 | G33: 100000 | H33: =SUM(C33:G33) -> 150000 | I33: 2 | J33: 2 | K33: —
A34: 13-3740011 | B34: Beautification & Horticulture | C34: 105500 | F34: 35000 | H34: =SUM(C34:G34) -> 140500 | I34: 8 | J34: 8 | K34: Carr; Hanks; Morano
A35: 82-4902021 | B35: Canvas Institute | C35: 65000 | F35: 75000 | H35: =SUM(C35:G35) -> 140000 | I35: 6 | J35: 5 | K35: Carr; Hanks; Morano; SI Delegation
A36: 13-3128315 | B36: On Your Mark, Inc. | C36: 70500 | E36: 9000 | F36: 35000 | G36: 25000 | H36: =SUM(C36:G36) -> 139500 | I36: 9 | J36: 7 | K36: Carr; Hanks; Morano; SI Delegation
A37: 13-3248928 | B37: Friends of Alice Austen House, Inc. | C37: 25000 | G37: 107500 | H37: =SUM(C37:G37) -> 132500 | I37: 5 | J37: 3 | K37: (citywide); Carr; Hanks; Morano
A38: 13-6202692 | B38: Chinese American Planning Council, Inc. | G38: 125000 | H38: =SUM(C38:G38) -> 125000 | I38: 2 | J38: 1
A39: 13-3046424 | B39: West Brighton Community Local Development Corporation | C39: 35000 | E39: 13000 | G39: 73070 | H39: =SUM(C39:G39) -> 121070 | I39: 5 | J39: 4 | K39: Hanks; SI Delegation
A40: 13-2738818 | B40: Metropolitan New York Coordinating Council on Jewish | C40: 112500 | H40: =SUM(C40:G40) -> 112500 | I40: 5 | J40: 5 | K40: Carr; Hanks; Morano
A41: 23-7379930 | B41: Staten Island Children's Museum | C41: 91000 | F41: 20000 | H41: =SUM(C41:G41) -> 111000 | I41: 7 | J41: 6 | K41: Carr; Hanks; Morano; —
...

Sheet Grand Total
A1: FY2027 STATEN ISLAND — CAPITAL + EXPENSE, COMBINED
A2: Capital: FY27 Adopted Section 254 capital changes (CC-verified Jul 1) + adopted capital workbook + office review Jul 2 (St. George add-on; $230K exclusion). Expense: Schedule C Final-3 parsed & reconciled; member figures tie the Council discretionary database.
A4: Component | B4: Amount | C4: Basis / source
A5: CAPITAL — Borough R (11 categories) | B5: 67964000 | C5: Section 254; Parks $22.908M … Higher Ed $500K
A6: CAPITAL — CC1100 SI DOT Trees & Sidewalk (Boro X-coded, SI Parks line D020) | B6: 3536000 | C6: Section 254; Speaker + Morano
A7: CAPITAL — MA1004 St. George Theatre ($5.85M, non-City section II/III — Measure-C-side wallet) | B7: 5850000 | C7: MA1004, PV 0N364, §254 V4 PDF p.67 — DOC-VERIFIED; org total $7,350,000 incl $1.5M CC (Carr/Hanks/Speaker $500K each)
A8: CAPITAL — SI-substantive total | B8: =B5+B6+B7 -> 77350000 | C8: Sum of the three lines above
A9: EXPENSE — MDIs, SI delegation members (printed) | B9: 6638000 | C9: Schedule C Final-3; database-tied
A10: EXPENSE — SI Delegation pot (Boroughwide, p.4) | B10: 120000 | C10: Schedule C Final-3
A11: EXPENSE — Speaker funding to SI | B11: 2817880 | C11: Pool $1.45M + designated $670K + untagged $698K
A12: EXPENSE — MDIs, other CMs to SI orgs | B12: 92000 | C12: MAS Bklyn&SI (bi-borough) + JCC-SI
A13: EXPENSE — Citywide initiatives to SI | B13: 6553360 | C13: 42 initiatives · 55 organization lines; Citywide tab (org-itemized) — rev Jul 6: +$25,000 Dibra/Welcome NYC p.151
A14: EXPENSE — printed SI total | B14: =SUM(B9:B13) -> 16221240 | C14: Scan basis
A15: EXPENSE — SU-CASA (database, unitemized) | B15: 90000 | C15: DB Jul 1; $3.825M pot 100% post-adoption
A16: GRAND — CAPITAL + EXPENSE, ALL-IN | B16: =B8+B14+B15 -> 93661240 | C16: SI-substantive capital + full expense scan + SU-CASA
A18: EXCLUDED & FLAGGED
A19: CC0796 (P.S./I.S. 229, Carr) — Boro-coded R, Brooklyn school codes: currently INSIDE the $71.5M; if Brooklyn, CC total → $71,270,000 | B19: 230000 | C19: DOC-VERIFIED as printed (B:K229 S:K229); Finance confirmation pending; §254 V4
A21: OFFICIAL MEASURES (stated bases — never blend)
A22: Measure A — delegation-controlled (established Jul 1) | B22: 74812000 | C22: Basis: Boro-R capital $67,964,000 + delegation discretionary $6,848,000
A23: Measure B — SI-substantive capital + delegation discretionary (established) | B23: 78348000 | C23: Basis: $71,500,000 + $6,848,000
A24: Measure B — recomputed with St. George add-on (PENDING adoption) | B24: 84198000 | C24: Basis: $77,350,000 + $6,848,000
A25: Measure C — all dollars reaching SI orgs, est. (established) | B25: 84018000 | C25: Basis: $71.5M + $6.848M + citywide-to-SI est $5.67M
A26: Measure C — recomputed with St. George add-on (PENDING adoption) | B26: 89868000 | C26: Basis: established C + $5,850,000
A27: Full-scan combined (this workbook) | B27: =B8+B14+B15 -> 93661240 | C27: Basis: $77.35M capital + $16,196,240 + SU-CASA $90K — broader than Measure C
A29: PROJECTION — ASSUMPTION LINE (not folded into confirmed totals)
A30: Morano SU-CASA assumed at delegation parity: 3 sites × $15,000 | B30: 45000 | C30: Assumption basis: Hanks and Carr each designated exactly 3×$15,000; D51 undesignated as of DB export
A31: PROJECTED GRAND — capital + expense, all-in, if realized | B31: =B16+B30 -> 93706240 | C31: Cascade if realized: delegation discretionary $6,848,000 → $6,893,000; Measures A/B/C each +$45,000 (A → $74,857,000)
A32: §254 context (as printed): Council Additions $853,688,000 · Rescindments ($23,317,000) · Net Change $830,371,000
A34: PDF ALL-FUNDING BASIS — APPLIED Jul 7, 2026 (do not mix with printed-basis lines above)
A35: Capital — SI-substantive (unchanged) | B35: 77350000 | C35: Ties existing three-component basis
A36: Expense — baseline CM pots (PDF allocation basis) | B36: 6773000 | C36: Hanks $2,295,000 · Carr $2,270,000 · Morano $2,208,000
A37: Expense — Speaker, corrected (F1: Ulqin + Project Hospitality removed) | B37: 2817880 | C37: Ties this tab’s prior Speaker line
A38: Expense — Citywide, PDF basis (90 lines) | B38: 8341467 | C38: Prior scan $6,553,360 + 26 added rows − Dibra dup − WB-only $10,000 + Delegation reclass — see Citywide Reconcile
A39: EXPENSE TOTAL — PDF corrected basis | B39: =SUM(B36:B38) -> 17932347 | C39: formula
A40: GRAND TOTAL — PDF corrected basis | B40: =B35+B39 -> 95282347 | C40: Equals printed PDF $95,332,347 less $50,000 F1
A41: GRAND TOTAL — PDF as printed | B41: 95332347 | C41: All-Funding PDF p.1

Sheet Source & Search Guide
A1: WHERE EVERY SI DOLLAR IS SEARCHABLE — PUBLIC SOURCE & SEARCH GUIDE
A2: Each channel in this workbook mapped to its public lookup path, with search keys and caveats. Verified Jul 2, 2026.
A4: What | B4: Where (public source) | C4: How to search | D4: Caveats
A5: Expense — every Schedule C line (MDIs, Speaker, citywide, delegation) | B5: Schedule C PDF — council.nyc.gov/budget/schedule-c/ | C5: By page (this workbook cites each line’s page); Ctrl-F org name or EIN in the PDF | D5: Revisions replace the posted file (Final → Final-3); post-adoption items (e.g., SU-CASA) absent until itemized
A6: Expense — dataset form, filter/sort/export | B6: NYC Open Data — "New York City Council Discretionary Funding" (dataset 4d7f-74pe, data.cityofnewyork.us) | C6: Filter by Council Member, organization, fiscal year; export CSV | D6: Reflects applications/allocations cycle; confirm against Schedule C for adopted status
A7: Expense — award clearance status per org | B7: MOCS Discretionary Award Tracker (nyc.gov/mocs → PASSPort articles) | C7: Search org LEGAL NAME or full EIN WITHOUT the dash; cleared = "Cleared – Contact Contracting Agency" | D7: Updates only every 6–8 weeks; defunded/reallocated awards may not display; Transparency-Resolution awards lag until Council transmits
A8: Expense — in-year changes & SU-CASA-type post-adoption itemization | B8: Transparency Resolutions — Legistar (legistar.council.nyc.gov) | C8: Search "Transparency Resolution" by stated-meeting date; designations list org, EIN, sponsor, amount | D8: This is where the pending SU-CASA names (incl. any Morano designations) will first appear
A9: Expense — actual payments to an org | B9: Checkbook NYC (checkbooknyc.com, Comptroller) | C9: Payee search by org name; filter agency & FY | D9: Shows spending once contracts register — lags designation by months
A10: Capital — every §254 Council addition (CC lines) | B10: §254 Supporting Detail PDF — council.nyc.gov budget page (this file: V4) | C10: By SUB ID (CC####) or PDF page as cited on the §254 tabs; Ctrl-F project title | D10: SPON column carries co-sponsorship in V4; CC0796 caveat noted
A11: Capital — MA/non-City lines (e.g., MA1004 St. George $5.85M) | B11: Same §254 PDF, Sections II & III (non-City detail + by-entity totals) | C11: Section III by ORGANIZATION for true org totals (St. George $7,350,000) | D11: MA lines excluded from the $853,688,000 Council Additions; no sponsor printed
A12: Capital — commitments & spend over time | B12: OMB Adopted Capital Commitment Plan (nyc.gov/omb) · Checkbook NYC capital | C12: Budget line (e.g., PV D477, HL DN404) in OMB; payee/project in Checkbook | D12: Commitment ≠ designation; timing spans years
A13: Capital — non-City org applications | B13: CapGrants portal (council.nyc.gov budget page) | C13: Org-side application records | D13: Application-side only
A14: Internal (not public) | B14: ExportedSearchResults.xlsx — Council Finance export | C14: This workbook’s member tabs; per-EIN, incl. SU-CASA pre-publication | D14: Authoritative for member designations; richer and earlier than any public source — do not cite externally

Sheet SI History FY23–27
A1: STATEN ISLAND SEATS — FIVE-YEAR MEMBER-DESIGNATED HISTORY (FY2023–FY2027)
A2: FY23–26: Council funded-disclosure workbook (all CMs). FY27: Council Finance database export. Same basis — member-designated designations incl. SU-CASA where filed.
A4: Seat / measure | B4: FY2023 | C4: FY2024 | D4: FY2025 | E4: FY2026 | F4: FY2027 | G4: 5-yr total | H4: Note
A5: Hanks (D49) | B5: 2295000 | C5: 2295000 | D5: 2365000 | E5: 2295000 | F5: 2295000 | G5: =SUM(B5:F5) -> 11545000 | H5: FY25 +$70,000 = one-year Food Pantries allocation — the entire bump
A6: Carr (D50) | B6: 2270000 | C6: 2270000 | D6: 2270000 | E6: 2270000 | F6: 2270000 | G6: =SUM(B6:F6) -> 11350000 | H6: Perfectly flat across all five years
A7: D51 seat — Borelli (FY23–25) → Morano (FY26–27) | B7: 2208000 | C7: 2208000 | D7: 2208000 | E7: 2208000 | F7: 2163000 | G7: =SUM(B7:F7) -> 10995000 | H7: Seat allocation identical through the special-election transition; FY27 −$45,000 = unfiled SU-CASA only
A8: THREE-SEAT TOTAL | B8: =SUM(B5:B7) -> 6773000 | C8: =SUM(C5:C7) -> 6773000 | D8: =SUM(D5:D7) -> 6843000 | E8: =SUM(E5:E7) -> 6773000 | F8: =SUM(F5:F7) -> 6728000 | G8: =SUM(B8:F8) -> 33890000 | H8: FY23–26 flat ~$6.77M; FY27 $6.73M pending SU-CASA
A9: SI Delegation pot | B9: 12000 | C9: 120000 | D9: 120000 | E9: 120000 | F9: 120000 | G9: =SUM(B9:F9) -> 492000 | H9: FY27 basis = Boroughwide Needs pot; −$378,213 vs FY26 — FLAGGED (basis check + Finance question pending)
A10: Citywide member-designated total | B10: 116261000 | C10: 116261000 | D10: 117276000 | E10: 118111000 | F10: 109853997 | G10: =SUM(B10:F10) -> 577762997 | H10: FY27 = Finance export subset; FY23–26 = disclosure totals
A11: SI three-seat share of citywide | B11: =B8/B10 -> 0.058256853 | C11: =C8/C10 -> 0.058256853 | D11: =D8/D10 -> 0.058349534 | E11: =E8/E10 -> 0.057344363 | F11: =F8/F10 -> 0.061244927 | H11: ≈ seat share (3/51 = 5.88%); the parity gap lives in citywide pots, not member money
A13: TIER STABILITY (formula placements, all five years): Hanks DoVE $195,000 & Anti-Poverty $50,000 every year; D51 seat DoVE $133,000 & Anti-Poverty $25,000 every year under both Borelli and Morano — the FY27 spreads are historic and structural, not annual discretion. Zero defunded/reallocated rows for any SI member, FY23–26.
A17: Yellow means under evaluation, should all be 120k a year

Sheet SI History — Continuity
A1: CONTINUITY VIEW — HANKS TOP ORGANIZATIONS ACROSS FIVE YEARS, AND THE D51 TRANSITION
A2: D51 smooth-transfer datapoint: Morano carried 74 of his 81 FY2026 organizations directly from Borelli’s FY2025 book — 91% continuity through the special election.
A4: Organization | B4: FY2023 | C4: FY2024 | D4: FY2025 | E4: FY2026 | F4: FY2027 | G4: 5-yr total
A5: Department of Sanitation | B5: 205000 | C5: 200000 | D5: 200000 | E5: 150000 | F5: 180000 | G5: =SUM(B5:F5) -> 935000
A6: Community Agency for Senior Citizens, Inc. | B6: 60000 | C6: 65000 | D6: 90000 | E6: 70000 | F6: 80000 | G6: =SUM(B6:F6) -> 365000
A7: Staten Island Chamber of Commerce Foundation, Inc. | B7: 45000 | C7: 70000 | D7: 50000 | E7: 75000 | F7: 120000 | G7: =SUM(B7:F7) -> 360000
A8: Snug Harbor Cultural Center & Botanical Garden | B8: 70000 | C8: 70000 | D8: 65000 | E8: 65000 | F8: 65000 | G8: =SUM(B8:F8) -> 335000
A9: New York Center for Interpersonal Development, Inc. | B9: 5000 | C9: 80000 | D9: 80000 | E9: 80000 | F9: 80000 | G9: =SUM(B9:F9) -> 325000
A10: Dr. Theodore A. Atlas Foundation, Inc. | B10: 5000 | C10: 35000 | D10: 97500 | E10: 84500 | F10: 80000 | G10: =SUM(B10:F10) -> 302000
A11: IlluminArt Productions | B11: 60000 | C11: 60000 | D11: 55000 | E11: 55000 | F11: 45000 | G11: =SUM(B11:F11) -> 275000
A12: City Parks Foundation | B12: 70000 | C12: 50000 | D12: 25000 | E12: 45000 | F12: 61000 | G12: =SUM(B12:F12) -> 251000
A13: Jewish Community Center of Staten Island, Inc. | B13: 50000 | C13: 50000 | D13: 50000 | E13: 50000 | F13: 50000 | G13: =SUM(B13:F13) -> 250000
A14: Department of Education | B14: 45500 | C14: 46500 | D14: 44000 | E14: 49000 | F14: 49000 | G14: =SUM(B14:F14) -> 234000
A15: Catholic Charities of Staten Island | B15: 55000 | C15: 55000 | D15: 30000 | E15: 30000 | F15: 60000 | G15: =SUM(B15:F15) -> 230000
A16: Seamen's Society for Children and Families | B16: 45000 | C16: 45000 | D16: 75000 | E16: 25000 | F16: 25000 | G16: =SUM(B16:F16) -> 215000
A18: Reading the trends: SI Chamber of Commerce Fdn rising ($45K → $120K, +167% over five years — the economic-development pillar compounding); NYCID stable at $80K since FY24 (plus the $500K Speaker Credible Messengers item on top); Snug Harbor ($65K) and JCC-SI ($50K) flat as institutional anchors; Seamen’s Society tapered after FY25. Supports the FY27 Seed → FY28 Grow succession framework.

Sheet §254 SI Capital (Sec I)
A1: FY 2027 CHANGES TO THE EXECUTIVE CAPITAL BUDGET PURSUANT TO SECTION 254 — CAPITAL PROJECT DETAIL (STATEN ISLAND LINES)
A2: Source: Supporting Detail V4 (uploaded Jul 2) — every Boro-R line plus CC1100 (Boro X, SI-substantive). Exact document style; SPON as printed.
A4: PHILOSOPHY PLAYGROUND RENOVATION
A5: SUB ID | B5: BUDGET LINE | C5: BORO | D5: PROJECT TITLE | E5: FY 2027 | F5: FY 2028 | G5: FY 2029 | H5: FY 2030 | I5: SPON | J5: PDF p.
A6: CC0791 | B6: ED001 | C6: R | D6: I.S.2 TECH UPGRADES B:R002 S:R002 | E6: 75000 | F6: 0 | G6: 0 | H6: 0 | I6: CARR | J6: 28
A7: CC0792 | B7: ED001 | C7: R | D7: I.S. 51 TECH UPGRADES B:R051 S:R051 | E7: 75000 | F7: 0 | G7: 0 | H7: 0 | I7: CARR | J7: 28
A8: CC0793 | B8: ED001 | C8: R | D8: P.S./I.S. 26 PARKING LOT B:R026 S:R026 | E8: 100000 | F8: 0 | G8: 0 | H8: 0 | I8: CARR | J8: 28
A9: CC0794 | B9: ED001 | C9: R | D9: P.S. 30 TECH UPGRADES B:R030 S:R030 | E9: 75000 | F9: 0 | G9: 0 | H9: 0 | I9: CARR | J9: 28
A10: CC0795 | B10: ED001 | C10: R | D10: P.S./I.S. 48 TECH UPGRADES B:R071 S:R048 | E10: 75000 | F10: 0 | G10: 0 | H10: 0 | I10: CARR | J10: 28
A11: CC0796 | B11: ED001 | C11: R | D11: P.S./I.S. 229 TECH UPGRADES B:K229 S:K229 | E11: 230000 | F11: 0 | G11: 0 | H11: 0 | I11: CARR | J11: 28
A12: CC0797 | B12: ED001 | C12: R | D12: P.S. 9 TECH UPGRADES B:R048 S:R009 | E12: 75000 | F12: 0 | G12: 0 | H12: 0 | I12: CARR | J12: 28
A13: CC0798 | B13: ED001 | C13: R | D13: P.S. 11 TECH UPGRADES B:R011 S:R011 | E13: 75000 | F13: 0 | G13: 0 | H13: 0 | I13: CARR | J13: 28
A14: CC0799 | B14: ED001 | C14: R | D14: P.S. 23 TECH UPGRADES B:R023 S:R023 | E14: 75000 | F14: 0 | G14: 0 | H14: 0 | I14: CARR | J14: 28
A15: CC0800 | B15: ED001 | C15: R | D15: P.S. 29 TECH UPGRADES B:R029 S:R029 | E15: 100000 | F15: 0 | G15: 0 | H15: 0 | I15: CARR | J15: 29
A16: CC0801 | B16: ED001 | C16: R | D16: P.S. 38 TECH UPGRADES B:R038 S:R038 | E16: 75000 | F16: 0 | G16: 0 | H16: 0 | I16: CARR | J16: 29
A17: CC0802 | B17: ED001 | C17: R | D17: P.S.39 GYM CONVERSION B:R039 S:R039 | E17: 500000 | F17: 0 | G17: 0 | H17: 0 | I17: CARR | J17: 29
... A52: CC0847 | B52: ED001 | C52: R | D52: I.S. 63 TECH UPGRADE B:R043 S:R063 | E52: 75000 | F52: 0 | G52: 0 | H52: 0 | I52: MORANO | J52: 30
D53: TOTALS FOR PHILOSOPHY PLAYGROUND RENOVATION (47 PROJECTS) | E53: =SUM(E6:E52) -> 7126000
A55: HEALTH AIDE & MEDICAL ASSISTANCE
A56: SUB ID | B56: BUDGET LINE | C56: BORO | D56: PROJECT TITLE | E56: FY 2027 | F56: FY 2028 | G56: FY 2029 | H56: FY 2030 | I56: SPON | J56: PDF p.
A57: CC0896 | B57: ED001 | C57: R | D57: P.S. 019 THE CURTIS SCHOOL TECH UPGRADES B:R019 S:R019 | E57: 75000 | F57: 0 | G57: 0 | H57: 0 | I57: HANKS | J57: 31
A58: CC0897 | B58: ED001 | C58: R | D58: P.S. 044 THOMAS C. BROWN TECH UPGRADE B:R044 S:R044 | E58: 70000 | F58: 0 | G58: 0 | H58: 0 | I58: HANKS | J58: 31
A59: CC0898 | B59: ED001 | C59: R | D59: P.S. 057 HUBERT H. HUMPHREY GYM UPGRADE B:R057 S:R057 | E59: 75000 | F59: 0 | G59: 0 | H59: 0 | I59: HANKS | J59: 31
A60: CC0899 | B60: ED001 | C60: R | D60: I.S. 49 BERTA A. DREYFUS STEAM LAB B:R049 S:R049 | E60: 250000 | F60: 0 | G60: 0 | H60: 0 | I60: HANKS | J60: 31
A61: CC0900 | B61: ED001 | C61: R | D61: THE EAGLE ACADEMY FOR YOUNG MEN OF STATEN ISLAND TECH UPGRADES B:R028 S:R028 | E61: 150000 | F61: 0 | G61: 0 | H61: 0 | I61: HANKS | J61: 31
A62: CC0901 | B62: ED001 | C62: R | D62: STATEN ISLAND SCHOOL OF CIVIC LEADERSHIP TECH UPGRADES B:R861 S:R861 | E62: 150000 | F62: 0 | G62: 0 | H62: 0 | I62: HANKS | J62: 31
D63: TOTALS FOR HEALTH AIDE & MEDICAL ASSISTANCE (6 PROJECTS) | E63: =SUM(E57:E62) -> 770000
A65: AND SOCIAL CHANGE CULINARY ARTS AND
A66: SUB ID | B66: BUDGET LINE | C66: BORO | D66: PROJECT TITLE | E66: FY 2027 | F66: FY 2028 | G66: FY 2029 | H66: FY 2030 | I66: SPON | J66: PDF p.
A67: CC1094 | B67: ED001 | C67: R | D67: P.S.50 PLAYGROUND RENOVATION | E67: 2000000 | F67: 0 | G67: 0 | H67: 0 | I67: SPEAKER CARR | J67: 34
A68: CC1095 | B68: ED001 | C68: R | D68: P.S. 60 PLAYGROUND RENOVATION | E68: 1800000 | F68: 0 | G68: 0 | H68: 0 | I68: SPEAKER CARR | J68: 34
D69: TOTALS FOR AND SOCIAL CHANGE CULINARY ARTS AND (2 PROJECTS) | E69: =SUM(E67:E68) -> 3800000
A71: ECONOMIC DEVELOPMENT
A72: SUB ID | B72: BUDGET LINE | C72: BORO | D72: PROJECT TITLE | E72: FY 2027 | F72: FY 2028 | G72: FY 2029 | H72: FY 2030 | I72: SPON | J72: PDF p.
A73: CC1090 | B73: EDD075 | C73: R | D73: NORTH SHORE ACTION PLAN - TOMPKINSVILLE | E73: 7000000 | F73: 0 | G73: 0 | H73: 0 | I73: SPEAKER HANKS | J73: 37
D74: TOTALS FOR ECONOMIC DEVELOPMENT (1 PROJECTS) | E74: =SUM(E73) -> 7000000
A76: ESPLANADE PROJECT
A77: SUB ID | B77: BUDGET LINE | C77: BORO | D77: PROJECT TITLE | E77: FY 2027 | F77: FY 2028 | G77: FY 2029 | H77: FY 2030 | I77: SPON | J77: PDF p.
A78: CC1092 | B78: EDD075 | C78: R | D78: PIER ONE FISHING PIER CONSTRUCTION | E78: 2500000 | F78: 0 | G78: 0 | H78: 0 | I78: SPEAKER HANKS | J78: 37
D79: TOTALS FOR ESPLANADE PROJECT (1 PROJECTS) | E79: =SUM(E78) -> 2500000
...

Sheet §254 SI Non-City (II & III)
A1: FY 2027 §254 — NON-CITY CAPITAL (SECTION II) & DETAIL BY NON-CITY ENTITY (SECTION III) — STATEN ISLAND
A3: SUB ID | B3: BUDGET LINE | C3: BORO | D3: PROJECT TITLE / ORGANIZATION | E3: FY 2027 | F3: SPON | G3: PDF p.
A4: SECTION II — the MA wallet (no sponsor; excluded from the $853,688,000 Council Additions)
A5: MA1004 | B5: PV0N364 | C5: R | D5: ST. GEORGE THEATRE RESTORATION, INC. | E5: 5850000 | F5: (none — non-City section) | G5: 67
A7: SECTION III — SI organizations, doc-printed org totals
A8: ST. GEORGE THEATER | D8: PV 0N364 $5,850,000 + PV DN364 $1,500,000 (CC0818 CARR $500K · CC0891 HANKS $500K · CC1098 SPEAKER $500K) | E8: 7350000
A9: STATEN ISLAND UNIVERSITY HOSPITAL | D9: HL DN404 (CC1091 501 Seaview $1,250,000 SPEAKER, HANKS · CC1147 Prince Bay $4,000,000 SPEAKER) | E9: 5250000
A10: ON YOUR MARK, INC. | D10: PW DN318 (CC0889 HANKS) | E10: 870000
A11: STATEN ISLAND JEWISH COMMUNITY CENTER | D11: PW DN402 (CC1162 CARR — vehicle) | E11: 365000
A12: VENTURE HOUSE INC. | D12: HL DN09D (CC0890 HANKS) | E12: 340000
D13: SI non-City org totals | E13: =SUM(E8:E12) -> 14175000
A15: DOCUMENT CONTEXT (as printed): City Council Additions $853,688,000 · Less Rescindments from Prior Capital Budgets ($23,317,000) · Net Change $830,371,000. Section II non-City total $210,677,000 (178 projects). The MA wallet citywide is dominated by cultural institutions (The Kitchen $14.0M · Ballet Hispánico $10.0M · Roundabout $7.0M · St. George $5.85M).

Sheet Capital — By Sponsor Detail
A1: SI CAPITAL BY SPONSOR — EVERY LINE, FROM THE §254 V4 SPON COLUMN (all prior LOCKED items now doc-verified)
A3: HANKS — 22 lines
A4: SUB ID | B4: PROJECT | C4: FY 2027 | D4: SPON (as printed) | E4: PDF p.
A5: CC1090 | B5: NORTH SHORE ACTION PLAN - TOMPKINSVILLE | C5: 7000000 | D5: SPEAKER HANKS | E5: 37
A6: CC1092 | B6: PIER ONE FISHING PIER CONSTRUCTION | C6: 2500000 | D6: SPEAKER HANKS | E6: 37
A7: CC1093 | B7: VOLUNTEERS OF AMERICA HILLSIDE GROVE | C7: 2000000 | D7: SPEAKER HANKS | E7: 42
A8: CC1091 | B8: STATEN ISLAND UNIVERSITY HOSPITAL 501 | C8: 1250000 | D8: SPEAKER HANKS | E8: 43
A9: CC0889 | B9: ON YOUR MARK RECREATIONAL FIELD | C9: 870000 | D9: HANKS | E9: 59
A10: CC0893 | B10: RICHMOND TERRACE STREET IMPROVEMENTS | C10: 500000 | D10: HANKS | E10: 48
A11: CC0894 | B11: BAY STREET AREA STREET IMPROVEMENTS | C11: 500000 | D11: HANKS | E11: 48
A12: CC0891 | B12: ST. GEORGE THEATER ROOF & FACADE | C12: 500000 | D12: HANKS | E12: 58
A13: CC0906 | B13: TAPPEN PARK PERIMETER RECONSTRUCTION | C13: 400000 | D13: HANKS | E13: 53
A14: CC0890 | B14: VENTURE HOUSE INC | C14: 340000 | D14: HANKS | E14: 43
A15: CC0899 | B15: I.S. 49 BERTA A. DREYFUS STEAM LAB B:R049 S:R049 | C15: 250000 | D15: HANKS | E15: 31
